Workbook

Sheet Leia-me
A1: Projeto Varejo — Esboço do dashboard em Excel
A2: As 20 perguntas de negócio, com tabelas de fórmulas, gráficos e espaço para as suas conclusões
B4: Base | C4: Aba Dados: cópia de data/processed/varejo_limpo, gerada pelo notebooks/03-diagnostico.ipynb (v1.1). 1.000 vendas de 2024, 17 colunas. Dataset fictício, para estudo.
B5: Como usar | C5: Cada aba numerada reúne um bloco de perguntas. Leia a tabela, olhe o gráfico e escreva a sua conclusão na área amarela. Atualize o Status no índice abaixo.
B6: Fórmulas | C6: Todos os números são fórmulas sobre a aba Dados, por nomes de intervalo (v_valor, v_mes, v_categoria…). Veja-os em Fórmulas → Gerenciador de Nomes. Se a base mudar, cole os novos dados na aba Dados mantendo as colunas e ajuste o tamanho dos nomes.
B7: Regras de filtro | C7: Pergunta 7 ignora as 260 vendas com preço imputado (preco_origem). Perguntas 18 a 20 ignoram as 69 vendas com desconto imputado (desconto_origem). 'Não informado' (canal) e 'NI' (UF) aparecem como linha própria e entram no faturamento.
B8: Próximo passo | C8: Este é um esboço. Para virar dashboard: recriar as tabelas como Tabelas Dinâmicas, ligar Segmentações de Dados (mês, canal, UF) e reunir os gráficos numa aba de painel.
B10: Legenda
B11: Área amarela | C11: Você preenche: conclusões, parâmetros e o Status do índice.
B12: Texto azul | C12: Parâmetro editável (limites RFV, faixas de desconto, massa mínima de UF).
B13: Azul-claro | C13: Indicador-chave calculado por fórmula. Não edite.
B14: Texto preto | C14: Fórmula. Não edite: altere os dados ou os parâmetros.
B15: Exemplo de conclusão | C15: "A receita mensal fica entre R$ X e R$ Y, sem tendência clara de alta ou queda; o pico de <mês> não se repete nos meses seguintes." — escreva no presente e cite os números.
B17: Índice das 20 perguntas
A18: Nº | B18: Bloco | C18: Pergunta | D18: Ir para | E18: Visual sugerido | F18: Status
A19: 1 | B19: Receita e Tendência | C19: A receita está crescendo, caindo ou estável ao longo de 2024? | D19: 1_Receita → | E19: Linha | F19: A fazer
A20: 2 | B20: Receita e Tendência | C20: Quais meses concentram mais vendas, acima da média do ano? | D20: 1_Receita → | E20: Barras + linha de média | F20: A fazer
A21: 3 | B21: Receita e Tendência | C21: O cliente está gastando mais ou menos por compra? | D21: 1_Receita → | E21: Linha | F21: A fazer
A22: 4 | B22: Receita e Tendência | C22: Quantas transações respondem por 80% da receita? | D22: 1_Receita → | E22: Pareto (curva acumulada) | F22: A fazer
A23: 5 | B23: Mix de Categorias | C23: Quais categorias sustentam o faturamento? | D23: 2_Categorias → | E23: Barras horizontais | F23: A fazer
A24: 6 | B24: Mix de Categorias | C24: Quais categorias vendem muito em unidades mas pouco em dinheiro? | D24: 2_Categorias → | E24: Dispersão (ou bolhas) | F24: A fazer
A25: 7 | B25: Mix de Categorias | C25: Qual o posicionamento e a variação de preço de cada categoria? | D25: 2_Categorias → | E25: Caixa (boxplot) | F25: A fazer
A26: 8 | B26: Mix de Categorias | C26: Alguma categoria está ganhando ou perdendo espaço ao longo do ano? | D26: 2_Categorias → | E26: Área empilhada 100% | F26: A fazer
A27: 9 | B27: Canais de Venda | C27: Quanto cada canal representa? | D27: 3_Canais → | E27: Rosca ou barras | F27: A fazer
A28: 10 | B28: Canais de Venda | C28: Em qual canal o cliente gasta mais por compra? | D28: 3_Canais → | E28: Barras horizontais | F28: A fazer
A29: 11 | B29: Canais de Venda | C29: O comportamento de compra muda conforme o canal? | D29: 3_Canais → | E29: Mapa de calor | F29: A fazer
A30: 12 | B30: Geografia | C30: Onde está concentrada a operação? | D30: 4_Geografia → | E30: Mapa preenchido ou barras | F30: A fazer
... A38: 20 | B38: Preço e Desconto | C38: Desconto maior gera venda maior? | D38: 6_Desconto → | E38: Dispersão com tendência | F38: A fazer
B40: Gerado em 27/10/2026 · esboço v1.0

Sheet 1_Receita
A1: Bloco 1 — Receita e Tendência
A2: Perguntas 1 a 4
A4: 1. Evolução mensal da receita
A5: Pergunta: a receita está crescendo, caindo ou estável ao longo de 2024?
A6: Como ler: a coluna Receita soma valor_total por mês. Olhe a tendência da linha, não um mês isolado.
A8: mês | B8: nome | C8: Receita | D8: Vendas | E8: Ticket médio | F8: Desvio vs média
A9: 1 | B9: Jan | C9: =SUMIFS(v_valor,v_mes,A9) -> 8995.65 | D9: =COUNTIFS(v_mes,A9) -> 96 | E9: =IFERROR(C9/D9,0) -> 93.704688 | F9: =C9/$C$22-1 -> -0.012772217
A10: 2 | B10: Fev | C10: =SUMIFS(v_valor,v_mes,A10) -> 7046.33 | D10: =COUNTIFS(v_mes,A10) -> 71 | E10: =IFERROR(C10/D10,0) -> 99.244085 | F10: =C10/$C$22-1 -> -0.22670038
A11: 3 | B11: Mar | C11: =SUMIFS(v_valor,v_mes,A11) -> 8135.14 | D11: =COUNTIFS(v_mes,A11) -> 100 | E11: =IFERROR(C11/D11,0) -> 81.3514 | F11: =C11/$C$22-1 -> -0.1072089
A12: 4 | B12: Abr | C12: =SUMIFS(v_valor,v_mes,A12) -> 6542.71 | D12: =COUNTIFS(v_mes,A12) -> 67 | E12: =IFERROR(C12/D12,0) -> 97.652388 | F12: =C12/$C$22-1 -> -0.28197016
A13: 5 | B13: Mai | C13: =SUMIFS(v_valor,v_mes,A13) -> 10142.67 | D13: =COUNTIFS(v_mes,A13) -> 91 | E13: =IFERROR(C13/D13,0) -> 111.45791 | F13: =C13/$C$22-1 -> 0.11310752
A14: 6 | B14: Jun | C14: =SUMIFS(v_valor,v_mes,A14) -> 7362.53 | D14: =COUNTIFS(v_mes,A14) -> 75 | E14: =IFERROR(C14/D14,0) -> 98.167067 | F14: =C14/$C$22-1 -> -0.191999
A15: 7 | B15: Jul | C15: =SUMIFS(v_valor,v_mes,A15) -> 11652.93 | D15: =COUNTIFS(v_mes,A15) -> 84 | E15: =IFERROR(C15/D15,0) -> 138.72536 | F15: =C15/$C$22-1 -> 0.27885103
A16: 8 | B16: Ago | C16: =SUMIFS(v_valor,v_mes,A16) -> 10403.65 | D16: =COUNTIFS(v_mes,A16) -> 97 | E16: =IFERROR(C16/D16,0) -> 107.25412 | F16: =C16/$C$22-1 -> 0.14174877
A17: 9 | B17: Set | C17: =SUMIFS(v_valor,v_mes,A17) -> 10750.49 | D17: =COUNTIFS(v_mes,A17) -> 83 | E17: =IFERROR(C17/D17,0) -> 129.52398 | F17: =C17/$C$22-1 -> 0.17981273
A18: 10 | B18: Out | C18: =SUMIFS(v_valor,v_mes,A18) -> 10432.27 | D18: =COUNTIFS(v_mes,A18) -> 71 | E18: =IFERROR(C18/D18,0) -> 146.93338 | F18: =C18/$C$22-1 -> 0.14488967
A19: 11 | B19: Nov | C19: =SUMIFS(v_valor,v_mes,A19) -> 10521.63 | D19: =COUNTIFS(v_mes,A19) -> 75 | E19: =IFERROR(C19/D19,0) -> 140.2884 | F19: =C19/$C$22-1 -> 0.15469649
A20: 12 | B20: Dez | C20: =SUMIFS(v_valor,v_mes,A20) -> 7358.37 | D20: =COUNTIFS(v_mes,A20) -> 90 | E20: =IFERROR(C20/D20,0) -> 81.759667 | F20: =C20/$C$22-1 -> -0.19245554
B21: Total | C21: =SUM(C9:C20) -> 109344.37 | D21: =SUM(D9:D20) -> 1000 | E21: =C21/D21 -> 109.34437
B22: Média mensal | C22: =AVERAGE(C9:C20) -> 9112.0308
B23: Conferência | C23: =IF(ABS(C21-SUM(v_valor))<0.01,"bate com a base","NÃO BATE") -> bate com a base
A25: Sua conclusão:
A26: Escreva aqui, com suas palavras, o que a tabela e o gráfico mostram.
A31: 2. Sazonalidade por mês
A32: Pergunta: quais meses concentram mais vendas, acima da média do ano?
A33: Como ler: use a coluna 'Desvio vs média' da tabela da pergunta 1: positivo = mês acima da média. No gráfico, as barras acima da linha são os meses fortes.
A35: mês | B35: nome | C35: Receita | D35: Média do ano | E35: Acima da média?
A36: =A9 -> 1 | B36: =B9 -> Jan | C36: =C9 -> 8995.65 | D36: =$C$22 -> 9112.0308 | E36: =IF(C36>D36,"Sim","Não") -> Não
A37: =A10 -> 2 | B37: =B10 -> Fev | C37: =C10 -> 7046.33 | D37: =$C$22 -> 9112.0308 | E37: =IF(C37>D37,"Sim","Não") -> Não
A38: =A11 -> 3 | B38: =B11 -> Mar | C38: =C11 -> 8135.14 | D38: =$C$22 -> 9112.0308 | E38: =IF(C38>D38,"Sim","Não") -> Não
A39: =A12 -> 4 | B39: =B12 -> Abr | C39: =C12 -> 6542.71 | D39: =$C$22 -> 9112.0308 | E39: =IF(C39>D39,"Sim","Não") -> Não
A40: =A13 -> 5 | B40: =B13 -> Mai | C40: =C13 -> 10142.67 | D40: =$C$22 -> 9112.0308 | E40: =IF(C40>D40,"Sim","Não") -> Sim
A41: =A14 -> 6 | B41: =B14 -> Jun | C41: =C14 -> 7362.53 | D41: =$C$22 -> 9112.0308 | E41: =IF(C41>D41,"Sim","Não") -> Não
A42: =A15 -> 7 | B42: =B15 -> Jul | C42: =C15 -> 11652.93 | D42: =$C$22 -> 9112.0308 | E42: =IF(C42>D42,"Sim","Não") -> Sim
A43: =A16 -> 8 | B43: =B16 -> Ago | C43: =C16 -> 10403.65 | D43: =$C$22 -> 9112.0308 | E43: =IF(C43>D43,"Sim","Não") -> Sim
A44: =A17 -> 9 | B44: =B17 -> Set | C44: =C17 -> 10750.49 | D44: =$C$22 -> 9112.0308 | E44: =IF(C44>D44,"Sim","Não") -> Sim
A45: =A18 -> 10 | B45: =B18 -> Out | C45: =C18 -> 10432.27 | D45: =$C$22 -> 9112.0308 | E45: =IF(C45>D45,"Sim","Não") -> Sim
A46: =A19 -> 11 | B46: =B19 -> Nov | C46: =C19 -> 10521.63 | D46: =$C$22 -> 9112.0308 | E46: =IF(C46>D46,"Sim","Não") -> Sim
A47: =A20 -> 12 | B47: =B20 -> Dez | C47: =C20 -> 7358.37 | D47: =$C$22 -> 9112.0308 | E47: =IF(C47>D47,"Sim","Não") -> Não
B48: Meses acima | C48: =COUNTIF(E36:E47,"Sim") -> 6
...

Sheet 2_Categorias
A1: Bloco 2 — Mix de Categorias
A2: Perguntas 5 a 8
A4: 5. Ranking de categorias por receita
A5: Pergunta: quais categorias sustentam o faturamento?
A6: Como ler: receita e participação de cada categoria. A coluna Posição ordena da maior para a menor.
A8: Categoria | B8: Receita | C8: % da receita | D8: Vendas | E8: Posição
A9: Mercearia | B9: =SUMIFS(v_valor,v_categoria,A9) -> 30008.46 | C9: =B9/SUM(v_valor) -> 0.27443992 | D9: =COUNTIFS(v_categoria,A9) -> 203 | E9: =RANK(B9,$B$9:$B$15) -> 1
A10: Bebidas | B10: =SUMIFS(v_valor,v_categoria,A10) -> 26172.15 | C10: =B10/SUM(v_valor) -> 0.23935526 | D10: =COUNTIFS(v_categoria,A10) -> 225 | E10: =RANK(B10,$B$9:$B$15) -> 2
A11: Limpeza | B11: =SUMIFS(v_valor,v_categoria,A11) -> 17880.79 | C11: =B11/SUM(v_valor) -> 0.1635273 | D11: =COUNTIFS(v_categoria,A11) -> 162 | E11: =RANK(B11,$B$9:$B$15) -> 3
A12: Frios | B12: =SUMIFS(v_valor,v_categoria,A12) -> 12390.32 | C12: =B12/SUM(v_valor) -> 0.11331466 | D12: =COUNTIFS(v_categoria,A12) -> 102 | E12: =RANK(B12,$B$9:$B$15) -> 4
A13: Higiene | B13: =SUMIFS(v_valor,v_categoria,A13) -> 8898.98 | C13: =B13/SUM(v_valor) -> 0.081384894 | D13: =COUNTIFS(v_categoria,A13) -> 75 | E13: =RANK(B13,$B$9:$B$15) -> 5
A14: Padaria | B14: =SUMIFS(v_valor,v_categoria,A14) -> 7820.41 | C14: =B14/SUM(v_valor) -> 0.071520921 | D14: =COUNTIFS(v_categoria,A14) -> 121 | E14: =RANK(B14,$B$9:$B$15) -> 6
A15: Hortifruti | B15: =SUMIFS(v_valor,v_categoria,A15) -> 6173.26 | C15: =B15/SUM(v_valor) -> 0.056457045 | D15: =COUNTIFS(v_categoria,A15) -> 112 | E15: =RANK(B15,$B$9:$B$15) -> 7
A16: Total | B16: =SUM(B9:B15) -> 109344.37 | C16: =SUM(C9:C15) -> 1
A18: Sua conclusão:
A19: Escreva aqui, com suas palavras, o que a tabela e o gráfico mostram.
A24: 6. Receita versus volume por categoria
A25: Pergunta: quais categorias vendem muito em unidades mas pouco em dinheiro — e vice-versa?
A26: Como ler: compare a participação em unidades com a participação em receita. Categoria com mais % de unidades que de receita atrai movimento; o contrário sustenta o caixa.
A28: Categoria | B28: Unidades | C28: Receita | D28: % unidades | E28: % receita | F28: Receita/unidade | G28: Perfil
A29: Mercearia | B29: =SUMIFS(v_qtd,v_categoria,A29) -> 557 | C29: =SUMIFS(v_valor,v_categoria,A29) -> 30008.46 | D29: =B29/SUM(v_qtd) -> 0.21026803 | E29: =C29/SUM(v_valor) -> 0.27443992 | F29: =C29/B29 -> 53.875153 | G29: =IF(D29>E29,"tráfego","valor") -> valor
A30: Bebidas | B30: =SUMIFS(v_qtd,v_categoria,A30) -> 589 | C30: =SUMIFS(v_valor,v_categoria,A30) -> 26172.15 | D30: =B30/SUM(v_qtd) -> 0.22234806 | E30: =C30/SUM(v_valor) -> 0.23935526 | F30: =C30/B30 -> 44.43489 | G30: =IF(D30>E30,"tráfego","valor") -> valor
A31: Limpeza | B31: =SUMIFS(v_qtd,v_categoria,A31) -> 430 | C31: =SUMIFS(v_valor,v_categoria,A31) -> 17880.79 | D31: =B31/SUM(v_qtd) -> 0.16232541 | E31: =C31/SUM(v_valor) -> 0.1635273 | F31: =C31/B31 -> 41.583233 | G31: =IF(D31>E31,"tráfego","valor") -> valor
A32: Frios | B32: =SUMIFS(v_qtd,v_categoria,A32) -> 268 | C32: =SUMIFS(v_valor,v_categoria,A32) -> 12390.32 | D32: =B32/SUM(v_qtd) -> 0.10117025 | E32: =C32/SUM(v_valor) -> 0.11331466 | F32: =C32/B32 -> 46.232537 | G32: =IF(D32>E32,"tráfego","valor") -> valor
A33: Higiene | B33: =SUMIFS(v_qtd,v_categoria,A33) -> 202 | C33: =SUMIFS(v_valor,v_categoria,A33) -> 8898.98 | D33: =B33/SUM(v_qtd) -> 0.076255191 | E33: =C33/SUM(v_valor) -> 0.081384894 | F33: =C33/B33 -> 44.054356 | G33: =IF(D33>E33,"tráfego","valor") -> valor
A34: Padaria | B34: =SUMIFS(v_qtd,v_categoria,A34) -> 313 | C34: =SUMIFS(v_valor,v_categoria,A34) -> 7820.41 | D34: =B34/SUM(v_qtd) -> 0.1181578 | E34: =C34/SUM(v_valor) -> 0.071520921 | F34: =C34/B34 -> 24.985335 | G34: =IF(D34>E34,"tráfego","valor") -> tráfego
A35: Hortifruti | B35: =SUMIFS(v_qtd,v_categoria,A35) -> 290 | C35: =SUMIFS(v_valor,v_categoria,A35) -> 6173.26 | D35: =B35/SUM(v_qtd) -> 0.10947527 | E35: =C35/SUM(v_valor) -> 0.056457045 | F35: =C35/B35 -> 21.287103 | G35: =IF(D35>E35,"tráfego","valor") -> tráfego
A37: Dica: para rotular cada ponto com o nome da categoria, clique na série → Adicionar Rótulos de Dados → Valor das Células (A da tabela).
A39: Sua conclusão:
A40: Escreva aqui, com suas palavras, o que a tabela e o gráfico mostram.
A45: 7. Dispersão de preço unitário por categoria
A46: Pergunta: qual o posicionamento e a variação de preço de cada categoria?
A47: Como ler: cinco números por categoria: mínimo, 1º quartil, mediana, 3º quartil e máximo. Usa só preços observados: as 260 vendas com preço imputado ficam de fora.
A49: Categoria | B49: Preços usados | C49: Mínimo | D49: 1º quartil | E49: Mediana | F49: 3º quartil | G49: Máximo | H49: Média
A50: Mercearia | B50: =COUNTIFS(v_categoria,A50,v_preco_origem,"<>imputado_mediana_categoria") -> 139 | C50: =_xlfn.MINIFS(v_preco,v_categoria,A50,v_preco_origem,"<>imputado_mediana_categoria") -> 3 | D50: {=PERCENTILE(IF((v_categoria=A50)*(v_preco_origem<>"imputado_mediana_categoria"),v_preco),0.25)} -> 5.05 | E50: {=PERCENTILE(IF((v_categoria=A50)*(v_preco_origem<>"imputado_mediana_categoria"),v_preco),0.5)} -> 29.18 | F50: {=PERCENTILE(IF((v_categoria=A50)*(v_preco_origem<>"imputado_mediana_categoria"),v_preco),0.75)} -> 78.195 | G50: =_xlfn.MAXIFS(v_preco,v_categoria,A50,v_preco_origem,"<>imputado_mediana_categoria") -> 239.17 | H50: =AVERAGEIFS(v_preco,v_categoria,A50,v_preco_origem,"<>imputado_mediana_categoria") -> 55.711583
A51: Bebidas | B51: =COUNTIFS(v_categoria,A51,v_preco_origem,"<>imputado_mediana_categoria") -> 170 | C51: =_xlfn.MINIFS(v_preco,v_categoria,A51,v_preco_origem,"<>imputado_mediana_categoria") -> 2.5 | D51: {=PERCENTILE(IF((v_categoria=A51)*(v_preco_origem<>"imputado_mediana_categoria"),v_preco),0.25)} -> 5.4875 | E51: {=PERCENTILE(IF((v_categoria=A51)*(v_preco_origem<>"imputado_mediana_categoria"),v_preco),0.5)} -> 30.44 | F51: {=PERCENTILE(IF((v_categoria=A51)*(v_preco_origem<>"imputado_mediana_categoria"),v_preco),0.75)} -> 77.09 | G51: =_xlfn.MAXIFS(v_preco,v_categoria,A51,v_preco_origem,"<>imputado_mediana_categoria") -> 177.16 | H51: =AVERAGEIFS(v_preco,v_categoria,A51,v_preco_origem,"<>imputado_mediana_categoria") -> 49.813294
A52: Limpeza | B52: =COUNTIFS(v_categoria,A52,v_preco_origem,"<>imputado_mediana_categoria") -> 127 | C52: =_xlfn.MINIFS(v_preco,v_categoria,A52,v_preco_origem,"<>imputado_mediana_categoria") -> 4 | D52: {=PERCENTILE(IF((v_categoria=A52)*(v_preco_origem<>"imputado_mediana_categoria"),v_preco),0.25)} -> 5.525 | E52: {=PERCENTILE(IF((v_categoria=A52)*(v_preco_origem<>"imputado_mediana_categoria"),v_preco),0.5)} -> 21.67 | F52: {=PERCENTILE(IF((v_categoria=A52)*(v_preco_origem<>"imputado_mediana_categoria"),v_preco),0.75)} -> 73.63 | G52: =_xlfn.MAXIFS(v_preco,v_categoria,A52,v_preco_origem,"<>imputado_mediana_categoria") -> 158.1 | H52: =AVERAGEIFS(v_preco,v_categoria,A52,v_preco_origem,"<>imputado_mediana_categoria") -> 44.300472
A53: Frios | B53: =COUNTIFS(v_categoria,A53,v_preco_origem,"<>imputado_mediana_categoria") -> 76 | C53: =_xlfn.MINIFS(v_preco,v_categoria,A53,v_preco_origem,"<>imputado_mediana_categoria") -> 6 | D53: {=PERCENTILE(IF((v_categoria=A53)*(v_preco_origem<>"imputado_mediana_categoria"),v_preco),0.25)} -> 9.915 | E53: {=PERCENTILE(IF((v_categoria=A53)*(v_preco_origem<>"imputado_mediana_categoria"),v_preco),0.5)} -> 28.195 | F53: {=PERCENTILE(IF((v_categoria=A53)*(v_preco_origem<>"imputado_mediana_categoria"),v_preco),0.75)} -> 86.3 | G53: =_xlfn.MAXIFS(v_preco,v_categoria,A53,v_preco_origem,"<>imputado_mediana_categoria") -> 207.34 | H53: =AVERAGEIFS(v_preco,v_categoria,A53,v_preco_origem,"<>imputado_mediana_categoria") -> 54.937105
A54: Higiene | B54: =COUNTIFS(v_categoria,A54,v_preco_origem,"<>imputado_mediana_categoria") -> 54 | C54: =_xlfn.MINIFS(v_preco,v_categoria,A54,v_preco_origem,"<>imputado_mediana_categoria") -> 3.5 | D54: {=PERCENTILE(IF((v_categoria=A54)*(v_preco_origem<>"imputado_mediana_categoria"),v_preco),0.25)} -> 6.5725 | E54: {=PERCENTILE(IF((v_categoria=A54)*(v_preco_origem<>"imputado_mediana_categoria"),v_preco),0.5)} -> 26.69 | F54: {=PERCENTILE(IF((v_categoria=A54)*(v_preco_origem<>"imputado_mediana_categoria"),v_preco),0.75)} -> 73.2225 | G54: =_xlfn.MAXIFS(v_preco,v_categoria,A54,v_preco_origem,"<>imputado_mediana_categoria") -> 145.03 | H54: =AVERAGEIFS(v_preco,v_categoria,A54,v_preco_origem,"<>imputado_mediana_categoria") -> 43.009259
A55: Padaria | B55: =COUNTIFS(v_categoria,A55,v_preco_origem,"<>imputado_mediana_categoria") -> 87 | C55: =_xlfn.MINIFS(v_preco,v_categoria,A55,v_preco_origem,"<>imputado_mediana_categoria") -> 1.5 | D55: {=PERCENTILE(IF((v_categoria=A55)*(v_preco_origem<>"imputado_mediana_categoria"),v_preco),0.25)} -> 3.74 | E55: {=PERCENTILE(IF((v_categoria=A55)*(v_preco_origem<>"imputado_mediana_categoria"),v_preco),0.5)} -> 18.33 | F55: {=PERCENTILE(IF((v_categoria=A55)*(v_preco_origem<>"imputado_mediana_categoria"),v_preco),0.75)} -> 38.445 | G55: =_xlfn.MAXIFS(v_preco,v_categoria,A55,v_preco_origem,"<>imputado_mediana_categoria") -> 87.89 | H55: =AVERAGEIFS(v_preco,v_categoria,A55,v_preco_origem,"<>imputado_mediana_categoria") -> 25.562184
...

Sheet 3_Canais
A1: Bloco 3 — Canais de Venda
A2: Perguntas 9 a 11 · 'Não informado' reúne as vendas sem canal registrado
A4: 9. Participação de receita por canal
A5: Pergunta: quanto cada canal (Loja, Site, App, Televendas) representa?
A6: Como ler: '% com canal' ignora as vendas sem canal; '% do total' as inclui. Os dois números contam histórias diferentes — cite qual está usando.
A8: Canal | B8: Receita | C8: % do total | D8: % com canal | E8: Vendas
A9: Loja | B9: =SUMIFS(v_valor,v_canal,A9) -> 38289.29 | C9: =B9/SUM(v_valor) -> 0.35017157 | D9: =IF(A9="Não informado","—",B9/(SUM(v_valor)-SUMIFS(v_valor,v_canal,"Não informado"))) -> 0.47126237 | E9: =COUNTIFS(v_canal,A9) -> 339
A10: Site | B10: =SUMIFS(v_valor,v_canal,A10) -> 23622.95 | C10: =B10/SUM(v_valor) -> 0.21604176 | D10: =IF(A10="Não informado","—",B10/(SUM(v_valor)-SUMIFS(v_valor,v_canal,"Não informado"))) -> 0.2907499 | E10: =COUNTIFS(v_canal,A10) -> 210
A11: App | B11: =SUMIFS(v_valor,v_canal,A11) -> 16769.02 | C11: =B11/SUM(v_valor) -> 0.1533597 | D11: =IF(A11="Não informado","—",B11/(SUM(v_valor)-SUMIFS(v_valor,v_canal,"Não informado"))) -> 0.20639213 | E11: =COUNTIFS(v_canal,A11) -> 180
A12: Televendas | B12: =SUMIFS(v_valor,v_canal,A12) -> 2567.09 | C12: =B12/SUM(v_valor) -> 0.023477112 | D12: =IF(A12="Não informado","—",B12/(SUM(v_valor)-SUMIFS(v_valor,v_canal,"Não informado"))) -> 0.031595595 | E12: =COUNTIFS(v_canal,A12) -> 38
A13: Não informado | B13: =SUMIFS(v_valor,v_canal,A13) -> 28096.02 | C13: =B13/SUM(v_valor) -> 0.25694985 | D13: =IF(A13="Não informado","—",B13/(SUM(v_valor)-SUMIFS(v_valor,v_canal,"Não informado"))) -> — | E13: =COUNTIFS(v_canal,A13) -> 233
A16: Sua conclusão:
A17: Escreva aqui, com suas palavras, o que a tabela e o gráfico mostram.
A22: 10. Ticket médio por canal
A23: Pergunta: em qual canal o cliente gasta mais por compra?
A24: Como ler: receita do canal ÷ número de vendas do canal.
A26: Canal | B26: Receita | C26: Vendas | D26: Ticket médio | E26: vs ticket geral
A27: Loja | B27: =SUMIFS(v_valor,v_canal,A27) -> 38289.29 | C27: =COUNTIFS(v_canal,A27) -> 339 | D27: =IFERROR(B27/C27,0) -> 112.94776 | E27: =D27/(SUM(v_valor)/COUNT(v_valor))-1 -> 0.032954492
A28: Site | B28: =SUMIFS(v_valor,v_canal,A28) -> 23622.95 | C28: =COUNTIFS(v_canal,A28) -> 210 | D28: =IFERROR(B28/C28,0) -> 112.49024 | E28: =D28/(SUM(v_valor)/COUNT(v_valor))-1 -> 0.02877028
A29: App | B29: =SUMIFS(v_valor,v_canal,A29) -> 16769.02 | C29: =COUNTIFS(v_canal,A29) -> 180 | D29: =IFERROR(B29/C29,0) -> 93.161222 | E29: =D29/(SUM(v_valor)/COUNT(v_valor))-1 -> -0.14800166
A30: Televendas | B30: =SUMIFS(v_valor,v_canal,A30) -> 2567.09 | C30: =COUNTIFS(v_canal,A30) -> 38 | D30: =IFERROR(B30/C30,0) -> 67.555 | E30: =D30/(SUM(v_valor)/COUNT(v_valor))-1 -> -0.38218127
A31: Não informado | B31: =SUMIFS(v_valor,v_canal,A31) -> 28096.02 | C31: =COUNTIFS(v_canal,A31) -> 233 | D31: =IFERROR(B31/C31,0) -> 120.58378 | E31: =D31/(SUM(v_valor)/COUNT(v_valor))-1 -> 0.10278908
A34: Sua conclusão:
A35: Escreva aqui, com suas palavras, o que a tabela e o gráfico mostram.
A40: 11. Mix de categorias dentro de cada canal
A41: Pergunta: o comportamento de compra muda conforme o canal?
A42: Como ler: participação de cada categoria na receita do canal (cada linha soma 100%). Cores mais fortes = categoria mais relevante naquele canal.
A44: Canal | B44: Mercearia | C44: Bebidas | D44: Limpeza | E44: Frios | F44: Higiene | G44: Padaria | H44: Hortifruti
A45: Loja | B45: =IFERROR(SUMIFS(v_valor,v_canal,$A45,v_categoria,B$44)/SUMIFS(v_valor,v_canal,$A45),0) -> 0.29191714 | C45: =IFERROR(SUMIFS(v_valor,v_canal,$A45,v_categoria,C$44)/SUMIFS(v_valor,v_canal,$A45),0) -> 0.22444161 | D45: =IFERROR(SUMIFS(v_valor,v_canal,$A45,v_categoria,D$44)/SUMIFS(v_valor,v_canal,$A45),0) -> 0.19128508 | E45: =IFERROR(SUMIFS(v_valor,v_canal,$A45,v_categoria,E$44)/SUMIFS(v_valor,v_canal,$A45),0) -> 0.12880103 | F45: =IFERROR(SUMIFS(v_valor,v_canal,$A45,v_categoria,F$44)/SUMIFS(v_valor,v_canal,$A45),0) -> 0.058299592 | G45: =IFERROR(SUMIFS(v_valor,v_canal,$A45,v_categoria,G$44)/SUMIFS(v_valor,v_canal,$A45),0) -> 0.045309015 | H45: =IFERROR(SUMIFS(v_valor,v_canal,$A45,v_categoria,H$44)/SUMIFS(v_valor,v_canal,$A45),0) -> 0.059946528
A46: Site | B46: =IFERROR(SUMIFS(v_valor,v_canal,$A46,v_categoria,B$44)/SUMIFS(v_valor,v_canal,$A46),0) -> 0.24144148 | C46: =IFERROR(SUMIFS(v_valor,v_canal,$A46,v_categoria,C$44)/SUMIFS(v_valor,v_canal,$A46),0) -> 0.20427127 | D46: =IFERROR(SUMIFS(v_valor,v_canal,$A46,v_categoria,D$44)/SUMIFS(v_valor,v_canal,$A46),0) -> 0.16551108 | E46: =IFERROR(SUMIFS(v_valor,v_canal,$A46,v_categoria,E$44)/SUMIFS(v_valor,v_canal,$A46),0) -> 0.15034066 | F46: =IFERROR(SUMIFS(v_valor,v_canal,$A46,v_categoria,F$44)/SUMIFS(v_valor,v_canal,$A46),0) -> 0.078869066 | G46: =IFERROR(SUMIFS(v_valor,v_canal,$A46,v_categoria,G$44)/SUMIFS(v_valor,v_canal,$A46),0) -> 0.096915923 | H46: =IFERROR(SUMIFS(v_valor,v_canal,$A46,v_categoria,H$44)/SUMIFS(v_valor,v_canal,$A46),0) -> 0.062650516
A47: App | B47: =IFERROR(SUMIFS(v_valor,v_canal,$A47,v_categoria,B$44)/SUMIFS(v_valor,v_canal,$A47),0) -> 0.278708 | C47: =IFERROR(SUMIFS(v_valor,v_canal,$A47,v_categoria,C$44)/SUMIFS(v_valor,v_canal,$A47),0) -> 0.25685818 | D47: =IFERROR(SUMIFS(v_valor,v_canal,$A47,v_categoria,D$44)/SUMIFS(v_valor,v_canal,$A47),0) -> 0.15168567 | E47: =IFERROR(SUMIFS(v_valor,v_canal,$A47,v_categoria,E$44)/SUMIFS(v_valor,v_canal,$A47),0) -> 0.081795478 | F47: =IFERROR(SUMIFS(v_valor,v_canal,$A47,v_categoria,F$44)/SUMIFS(v_valor,v_canal,$A47),0) -> 0.07997128 | G47: =IFERROR(SUMIFS(v_valor,v_canal,$A47,v_categoria,G$44)/SUMIFS(v_valor,v_canal,$A47),0) -> 0.06598716 | H47: =IFERROR(SUMIFS(v_valor,v_canal,$A47,v_categoria,H$44)/SUMIFS(v_valor,v_canal,$A47),0) -> 0.084994233
A48: Televendas | B48: =IFERROR(SUMIFS(v_valor,v_canal,$A48,v_categoria,B$44)/SUMIFS(v_valor,v_canal,$A48),0) -> 0.61996268 | C48: =IFERROR(SUMIFS(v_valor,v_canal,$A48,v_categoria,C$44)/SUMIFS(v_valor,v_canal,$A48),0) -> 0.15801939 | D48: =IFERROR(SUMIFS(v_valor,v_canal,$A48,v_categoria,D$44)/SUMIFS(v_valor,v_canal,$A48),0) -> 0.024989385 | E48: =IFERROR(SUMIFS(v_valor,v_canal,$A48,v_categoria,E$44)/SUMIFS(v_valor,v_canal,$A48),0) -> 0.018920256 | F48: =IFERROR(SUMIFS(v_valor,v_canal,$A48,v_categoria,F$44)/SUMIFS(v_valor,v_canal,$A48),0) -> 0.030797518 | G48: =IFERROR(SUMIFS(v_valor,v_canal,$A48,v_categoria,G$44)/SUMIFS(v_valor,v_canal,$A48),0) -> 0.085287232 | H48: =IFERROR(SUMIFS(v_valor,v_canal,$A48,v_categoria,H$44)/SUMIFS(v_valor,v_canal,$A48),0) -> 0.062023536
A49: Não informado | B49: =IFERROR(SUMIFS(v_valor,v_canal,$A49,v_categoria,B$44)/SUMIFS(v_valor,v_canal,$A49),0) -> 0.24424954 | C49: =IFERROR(SUMIFS(v_valor,v_canal,$A49,v_categoria,C$44)/SUMIFS(v_valor,v_canal,$A49),0) -> 0.28616295 | D49: =IFERROR(SUMIFS(v_valor,v_canal,$A49,v_categoria,D$44)/SUMIFS(v_valor,v_canal,$A49),0) -> 0.14375666 | E49: =IFERROR(SUMIFS(v_valor,v_canal,$A49,v_categoria,E$44)/SUMIFS(v_valor,v_canal,$A49),0) -> 0.088515384 | F49: =IFERROR(SUMIFS(v_valor,v_canal,$A49,v_categoria,F$44)/SUMIFS(v_valor,v_canal,$A49),0) -> 0.12042667 | G49: =IFERROR(SUMIFS(v_valor,v_canal,$A49,v_categoria,G$44)/SUMIFS(v_valor,v_canal,$A49),0) -> 0.087935587 | H49: =IFERROR(SUMIFS(v_valor,v_canal,$A49,v_categoria,H$44)/SUMIFS(v_valor,v_canal,$A49),0) -> 0.028953211
A52: Sua conclusão:
A53: Escreva aqui, com suas palavras, o que a tabela e o gráfico mostram.

Sheet 4_Geografia
A1: Bloco 4 — Geografia
A2: Perguntas 12 a 14 · 'NI' reúne as vendas sem UF registrada
A4: 12. Receita por unidade federativa
A5: Pergunta: onde está concentrada a operação?
A6: Como ler: UFs ordenadas pela receita; 'NI' fica sempre por último. Atenção às UFs com poucas vendas: a média delas oscila muito.
A8: UF | B8: Receita | C8: % do total | D8: Vendas | E8: Posição | F8: Massa ≥ 15?
A9: SP | B9: =SUMIFS(v_valor,v_uf,A9) -> 22877.15 | C9: =B9/SUM(v_valor) -> 0.20922111 | D9: =COUNTIFS(v_uf,A9) -> 227 | E9: =RANK(B9,$B$9:$B$23) -> 1 | F9: =IF(D9>=4_Geografia!$C$26,"sim","não") -> sim
A10: MG | B10: =SUMIFS(v_valor,v_uf,A10) -> 9957 | C10: =B10/SUM(v_valor) -> 0.09106093 | D10: =COUNTIFS(v_uf,A10) -> 79 | E10: =RANK(B10,$B$9:$B$23) -> 2 | F10: =IF(D10>=4_Geografia!$C$26,"sim","não") -> sim
A11: BA | B11: =SUMIFS(v_valor,v_uf,A11) -> 8549.11 | C11: =B11/SUM(v_valor) -> 0.078185187 | D11: =COUNTIFS(v_uf,A11) -> 54 | E11: =RANK(B11,$B$9:$B$23) -> 3 | F11: =IF(D11>=4_Geografia!$C$26,"sim","não") -> sim
A12: RJ | B12: =SUMIFS(v_valor,v_uf,A12) -> 7484.96 | C12: =B12/SUM(v_valor) -> 0.06845309 | D12: =COUNTIFS(v_uf,A12) -> 94 | E12: =RANK(B12,$B$9:$B$23) -> 4 | F12: =IF(D12>=4_Geografia!$C$26,"sim","não") -> sim
A13: CE | B13: =SUMIFS(v_valor,v_uf,A13) -> 5699.85 | C13: =B13/SUM(v_valor) -> 0.052127512 | D13: =COUNTIFS(v_uf,A13) -> 41 | E13: =RANK(B13,$B$9:$B$23) -> 5 | F13: =IF(D13>=4_Geografia!$C$26,"sim","não") -> sim
A14: RS | B14: =SUMIFS(v_valor,v_uf,A14) -> 5225.46 | C14: =B14/SUM(v_valor) -> 0.047789017 | D14: =COUNTIFS(v_uf,A14) -> 43 | E14: =RANK(B14,$B$9:$B$23) -> 6 | F14: =IF(D14>=4_Geografia!$C$26,"sim","não") -> sim
A15: PE | B15: =SUMIFS(v_valor,v_uf,A15) -> 5064.29 | C15: =B15/SUM(v_valor) -> 0.04631505 | D15: =COUNTIFS(v_uf,A15) -> 36 | E15: =RANK(B15,$B$9:$B$23) -> 7 | F15: =IF(D15>=4_Geografia!$C$26,"sim","não") -> sim
A16: ES | B16: =SUMIFS(v_valor,v_uf,A16) -> 4022.49 | C16: =B16/SUM(v_valor) -> 0.036787354 | D16: =COUNTIFS(v_uf,A16) -> 22 | E16: =RANK(B16,$B$9:$B$23) -> 8 | F16: =IF(D16>=4_Geografia!$C$26,"sim","não") -> sim
A17: PR | B17: =SUMIFS(v_valor,v_uf,A17) -> 3879.87 | C17: =B17/SUM(v_valor) -> 0.035483034 | D17: =COUNTIFS(v_uf,A17) -> 40 | E17: =RANK(B17,$B$9:$B$23) -> 9 | F17: =IF(D17>=4_Geografia!$C$26,"sim","não") -> sim
A18: GO | B18: =SUMIFS(v_valor,v_uf,A18) -> 3860.62 | C18: =B18/SUM(v_valor) -> 0.035306985 | D18: =COUNTIFS(v_uf,A18) -> 33 | E18: =RANK(B18,$B$9:$B$23) -> 10 | F18: =IF(D18>=4_Geografia!$C$26,"sim","não") -> sim
A19: MA | B19: =SUMIFS(v_valor,v_uf,A19) -> 3248.4 | C19: =B19/SUM(v_valor) -> 0.029707977 | D19: =COUNTIFS(v_uf,A19) -> 17 | E19: =RANK(B19,$B$9:$B$23) -> 11 | F19: =IF(D19>=4_Geografia!$C$26,"sim","não") -> sim
A20: PA | B20: =SUMIFS(v_valor,v_uf,A20) -> 2621.45 | C20: =B20/SUM(v_valor) -> 0.023974257 | D20: =COUNTIFS(v_uf,A20) -> 24 | E20: =RANK(B20,$B$9:$B$23) -> 12 | F20: =IF(D20>=4_Geografia!$C$26,"sim","não") -> sim
... A23: PB | B23: =SUMIFS(v_valor,v_uf,A23) -> 1259.45 | C23: =B23/SUM(v_valor) -> 0.011518197 | D23: =COUNTIFS(v_uf,A23) -> 15 | E23: =RANK(B23,$B$9:$B$23) -> 15 | F23: =IF(D23>=4_Geografia!$C$26,"sim","não") -> sim
A24: NI | B24: =SUMIFS(v_valor,v_uf,A24) -> 21653.52 | C24: =B24/SUM(v_valor) -> 0.1980305 | D24: =COUNTIFS(v_uf,A24) -> 243 | E24: — | F24: =IF(D24>=4_Geografia!$C$26,"sim","não") -> sim
A26: Mínimo de vendas para considerar a UF: | C26: 15
A28: Dica para o dashboard final: selecione UF e Receita e use Inserir → Mapas → Mapa Preenchido. O 'NI' deve ficar fora do mapa.
A30: Sua conclusão:
A31: Escreva aqui, com suas palavras, o que a tabela e o gráfico mostram.
A36: 13. Grau de concentração geográfica
A37: Pergunta: qual a dependência das praças principais?
A38: Como ler: quanto da receita vem das 3 e das 5 maiores UFs. Dois denominadores: o faturamento total e só a receita com UF informada.
A40: Indicador | C40: Receita | D40: % do total | E40: % com UF
A41: Top 3 UFs | C41: =SUMPRODUCT(LARGE($B$9:$B$23,{1,2,3})) -> 41383.26 | D41: =C41/SUM(v_valor) -> 0.37846722 | E41: =C41/SUM($B$9:$B$23) -> 0.47192221
A42: Top 5 UFs | C42: =SUMPRODUCT(LARGE($B$9:$B$23,{1,2,3,4,5})) -> 54568.07 | D42: =C42/SUM(v_valor) -> 0.49904782 | E42: =C42/SUM($B$9:$B$23) -> 0.62227781
A44: Sua conclusão:
A45: Escreva aqui, com suas palavras, o que a tabela e o gráfico mostram.
A50: 14. Canal preferencial por região
A51: Pergunta: o canal de compra varia geograficamente?
A52: Como ler: participação de cada canal no número de vendas da UF (cada linha soma 100%). Compare só UFs com 'Massa ≥ 15?' = sim.
A54: UF | B54: Loja | C54: Site | D54: App | E54: Televendas | F54: Não informado | G54: Vendas
A55: SP | B55: =IFERROR(COUNTIFS(v_uf,$A55,v_canal,B$54)/COUNTIFS(v_uf,$A55),0) -> 0.33920705 | C55: =IFERROR(COUNTIFS(v_uf,$A55,v_canal,C$54)/COUNTIFS(v_uf,$A55),0) -> 0.17621145 | D55: =IFERROR(COUNTIFS(v_uf,$A55,v_canal,D$54)/COUNTIFS(v_uf,$A55),0) -> 0.20264317 | E55: =IFERROR(COUNTIFS(v_uf,$A55,v_canal,E$54)/COUNTIFS(v_uf,$A55),0) -> 0.052863436 | F55: =IFERROR(COUNTIFS(v_uf,$A55,v_canal,F$54)/COUNTIFS(v_uf,$A55),0) -> 0.22907489 | G55: =COUNTIFS(v_uf,$A55) -> 227
A56: MG | B56: =IFERROR(COUNTIFS(v_uf,$A56,v_canal,B$54)/COUNTIFS(v_uf,$A56),0) -> 0.40506329 | C56: =IFERROR(COUNTIFS(v_uf,$A56,v_canal,C$54)/COUNTIFS(v_uf,$A56),0) -> 0.24050633 | D56: =IFERROR(COUNTIFS(v_uf,$A56,v_canal,D$54)/COUNTIFS(v_uf,$A56),0) -> 0.15189873 | E56: =IFERROR(COUNTIFS(v_uf,$A56,v_canal,E$54)/COUNTIFS(v_uf,$A56),0) -> 0.012658228 | F56: =IFERROR(COUNTIFS(v_uf,$A56,v_canal,F$54)/COUNTIFS(v_uf,$A56),0) -> 0.18987342 | G56: =COUNTIFS(v_uf,$A56) -> 79
A57: BA | B57: =IFERROR(COUNTIFS(v_uf,$A57,v_canal,B$54)/COUNTIFS(v_uf,$A57),0) -> 0.37037037 | C57: =IFERROR(COUNTIFS(v_uf,$A57,v_canal,C$54)/COUNTIFS(v_uf,$A57),0) -> 0.16666667 | D57: =IFERROR(COUNTIFS(v_uf,$A57,v_canal,D$54)/COUNTIFS(v_uf,$A57),0) -> 0.14814815 | E57: =IFERROR(COUNTIFS(v_uf,$A57,v_canal,E$54)/COUNTIFS(v_uf,$A57),0) -> 0.037037037 | F57: =IFERROR(COUNTIFS(v_uf,$A57,v_canal,F$54)/COUNTIFS(v_uf,$A57),0) -> 0.27777778 | G57: =COUNTIFS(v_uf,$A57) -> 54
A58: RJ | B58: =IFERROR(COUNTIFS(v_uf,$A58,v_canal,B$54)/COUNTIFS(v_uf,$A58),0) -> 0.37234043 | C58: =IFERROR(COUNTIFS(v_uf,$A58,v_canal,C$54)/COUNTIFS(v_uf,$A58),0) -> 0.21276596 | D58: =IFERROR(COUNTIFS(v_uf,$A58,v_canal,D$54)/COUNTIFS(v_uf,$A58),0) -> 0.18085106 | E58: =IFERROR(COUNTIFS(v_uf,$A58,v_canal,E$54)/COUNTIFS(v_uf,$A58),0) -> 0.021276596 | F58: =IFERROR(COUNTIFS(v_uf,$A58,v_canal,F$54)/COUNTIFS(v_uf,$A58),0) -> 0.21276596 | G58: =COUNTIFS(v_uf,$A58) -> 94
...

Sheet 5_Clientes
A1: Bloco 5 — Clientes
A2: Perguntas 15 a 17 · cálculos por cliente na aba aux_clientes (245 clientes)
A4: 15. Recorrência de compra
A5: Pergunta: qual a proporção de clientes recorrentes na base?
A6: Como ler: quantos clientes compraram 1 vez, 2 vezes, e assim por diante. Recorrente = 2 compras ou mais.
A8: Compras | B8: Clientes | C8: % dos clientes
A9: 1 | B9: =COUNTIF(aux_clientes!$B$2:$B$246,A9) -> 15 | C9: =B9/COUNTA(aux_clientes!$A$2:$A$246) -> 0.06122449
A10: 2 | B10: =COUNTIF(aux_clientes!$B$2:$B$246,A10) -> 41 | C10: =B10/COUNTA(aux_clientes!$A$2:$A$246) -> 0.16734694
A11: 3 | B11: =COUNTIF(aux_clientes!$B$2:$B$246,A11) -> 48 | C11: =B11/COUNTA(aux_clientes!$A$2:$A$246) -> 0.19591837
A12: 4 | B12: =COUNTIF(aux_clientes!$B$2:$B$246,A12) -> 45 | C12: =B12/COUNTA(aux_clientes!$A$2:$A$246) -> 0.18367347
A13: 5 | B13: =COUNTIF(aux_clientes!$B$2:$B$246,A13) -> 48 | C13: =B13/COUNTA(aux_clientes!$A$2:$A$246) -> 0.19591837
A14: 6 | B14: =COUNTIF(aux_clientes!$B$2:$B$246,A14) -> 18 | C14: =B14/COUNTA(aux_clientes!$A$2:$A$246) -> 0.073469388
A15: 7 | B15: =COUNTIF(aux_clientes!$B$2:$B$246,A15) -> 18 | C15: =B15/COUNTA(aux_clientes!$A$2:$A$246) -> 0.073469388
A16: 8 | B16: =COUNTIF(aux_clientes!$B$2:$B$246,A16) -> 5 | C16: =B16/COUNTA(aux_clientes!$A$2:$A$246) -> 0.020408163
A17: 9 | B17: =COUNTIF(aux_clientes!$B$2:$B$246,A17) -> 5 | C17: =B17/COUNTA(aux_clientes!$A$2:$A$246) -> 0.020408163
A18: 10 | B18: =COUNTIF(aux_clientes!$B$2:$B$246,A18) -> 2 | C18: =B18/COUNTA(aux_clientes!$A$2:$A$246) -> 0.0081632653
A19: 11 | B19: =COUNTIF(aux_clientes!$B$2:$B$246,A19) -> 0 | C19: =B19/COUNTA(aux_clientes!$A$2:$A$246) -> 0
A20: 12 | B20: =COUNTIF(aux_clientes!$B$2:$B$246,A20) -> 0 | C20: =B20/COUNTA(aux_clientes!$A$2:$A$246) -> 0
A22: Clientes | B22: =COUNTA(aux_clientes!$A$2:$A$246) -> 245
A23: Recorrentes (2+ compras) | B23: =COUNTIF(aux_clientes!$B$2:$B$246,">=2") -> 230
A24: % recorrentes | B24: =B23/B22 -> 0.93877551
A25: Compras por cliente (média) | B25: =AVERAGE(aux_clientes!$B$2:$B$246) -> 4.0816327
A27: Sua conclusão:
A28: Escreva aqui, com suas palavras, o que a tabela e o gráfico mostram.
A33: 16. Top clientes por receita
A34: Pergunta: quem são os clientes de maior valor?
A35: Como ler: os 20 clientes com maior receita no ano. A coluna '% acumulado' mostra quanto eles somam juntos.
A37: Posição | B37: Cliente | C37: Receita | D37: Compras | E37: % da receita | F37: % acumulado
A38: 1 | B38: =INDEX(aux_clientes!$A$2:$A$246,MATCH(LARGE(aux_clientes!$F$2:$F$246,A38),aux_clientes!$F$2:$F$246,0)) -> CLI-0149 | C38: =INDEX(aux_clientes!$C$2:$C$246,MATCH(LARGE(aux_clientes!$F$2:$F$246,A38),aux_clientes!$F$2:$F$246,0)) -> 1770.31 | D38: =INDEX(aux_clientes!$B$2:$B$246,MATCH(LARGE(aux_clientes!$F$2:$F$246,A38),aux_clientes!$F$2:$F$246,0)) -> 7 | E38: =C38/SUM(v_valor) -> 0.016190225 | F38: =SUM($E$38:E38) -> 0.016190225
A39: 2 | B39: =INDEX(aux_clientes!$A$2:$A$246,MATCH(LARGE(aux_clientes!$F$2:$F$246,A39),aux_clientes!$F$2:$F$246,0)) -> CLI-0096 | C39: =INDEX(aux_clientes!$C$2:$C$246,MATCH(LARGE(aux_clientes!$F$2:$F$246,A39),aux_clientes!$F$2:$F$246,0)) -> 1740.39 | D39: =INDEX(aux_clientes!$B$2:$B$246,MATCH(LARGE(aux_clientes!$F$2:$F$246,A39),aux_clientes!$F$2:$F$246,0)) -> 8 | E39: =C39/SUM(v_valor) -> 0.015916595 | F39: =SUM($E$38:E39) -> 0.03210682
A40: 3 | B40: =INDEX(aux_clientes!$A$2:$A$246,MATCH(LARGE(aux_clientes!$F$2:$F$246,A40),aux_clientes!$F$2:$F$246,0)) -> CLI-0250 | C40: =INDEX(aux_clientes!$C$2:$C$246,MATCH(LARGE(aux_clientes!$F$2:$F$246,A40),aux_clientes!$F$2:$F$246,0)) -> 1718.86 | D40: =INDEX(aux_clientes!$B$2:$B$246,MATCH(LARGE(aux_clientes!$F$2:$F$246,A40),aux_clientes!$F$2:$F$246,0)) -> 7 | E40: =C40/SUM(v_valor) -> 0.015719694 | F40: =SUM($E$38:E40) -> 0.047826514
A41: 4 | B41: =INDEX(aux_clientes!$A$2:$A$246,MATCH(LARGE(aux_clientes!$F$2:$F$246,A41),aux_clientes!$F$2:$F$246,0)) -> CLI-0037 | C41: =INDEX(aux_clientes!$C$2:$C$246,MATCH(LARGE(aux_clientes!$F$2:$F$246,A41),aux_clientes!$F$2:$F$246,0)) -> 1614.56 | D41: =INDEX(aux_clientes!$B$2:$B$246,MATCH(LARGE(aux_clientes!$F$2:$F$246,A41),aux_clientes!$F$2:$F$246,0)) -> 6 | E41: =C41/SUM(v_valor) -> 0.014765827 | F41: =SUM($E$38:E41) -> 0.06259234
A42: 5 | B42: =INDEX(aux_clientes!$A$2:$A$246,MATCH(LARGE(aux_clientes!$F$2:$F$246,A42),aux_clientes!$F$2:$F$246,0)) -> CLI-0137 | C42: =INDEX(aux_clientes!$C$2:$C$246,MATCH(LARGE(aux_clientes!$F$2:$F$246,A42),aux_clientes!$F$2:$F$246,0)) -> 1576.78 | D42: =INDEX(aux_clientes!$B$2:$B$246,MATCH(LARGE(aux_clientes!$F$2:$F$246,A42),aux_clientes!$F$2:$F$246,0)) -> 6 | E42: =C42/SUM(v_valor) -> 0.014420313 | F42: =SUM($E$38:E42) -> 0.077012653
A43: 6 | B43: =INDEX(aux_clientes!$A$2:$A$246,MATCH(LARGE(aux_clientes!$F$2:$F$246,A43),aux_clientes!$F$2:$F$246,0)) -> CLI-0042 | C43: =INDEX(aux_clientes!$C$2:$C$246,MATCH(LARGE(aux_clientes!$F$2:$F$246,A43),aux_clientes!$F$2:$F$246,0)) -> 1570.61 | D43: =INDEX(aux_clientes!$B$2:$B$246,MATCH(LARGE(aux_clientes!$F$2:$F$246,A43),aux_clientes!$F$2:$F$246,0)) -> 3 | E43: =C43/SUM(v_valor) -> 0.014363885 | F43: =SUM($E$38:E43) -> 0.091376538
A44: 7 | B44: =INDEX(aux_clientes!$A$2:$A$246,MATCH(LARGE(aux_clientes!$F$2:$F$246,A44),aux_clientes!$F$2:$F$246,0)) -> CLI-0021 | C44: =INDEX(aux_clientes!$C$2:$C$246,MATCH(LARGE(aux_clientes!$F$2:$F$246,A44),aux_clientes!$F$2:$F$246,0)) -> 1511.7 | D44: =INDEX(aux_clientes!$B$2:$B$246,MATCH(LARGE(aux_clientes!$F$2:$F$246,A44),aux_clientes!$F$2:$F$246,0)) -> 5 | E44: =C44/SUM(v_valor) -> 0.013825129 | F44: =SUM($E$38:E44) -> 0.10520167
A45: 8 | B45: =INDEX(aux_clientes!$A$2:$A$246,MATCH(LARGE(aux_clientes!$F$2:$F$246,A45),aux_clientes!$F$2:$F$246,0)) -> CLI-0214 | C45: =INDEX(aux_clientes!$C$2:$C$246,MATCH(LARGE(aux_clientes!$F$2:$F$246,A45),aux_clientes!$F$2:$F$246,0)) -> 1457.49 | D45: =INDEX(aux_clientes!$B$2:$B$246,MATCH(LARGE(aux_clientes!$F$2:$F$246,A45),aux_clientes!$F$2:$F$246,0)) -> 2 | E45: =C45/SUM(v_valor) -> 0.013329356 | F45: =SUM($E$38:E45) -> 0.11853102
A46: 9 | B46: =INDEX(aux_clientes!$A$2:$A$246,MATCH(LARGE(aux_clientes!$F$2:$F$246,A46),aux_clientes!$F$2:$F$246,0)) -> CLI-0004 | C46: =INDEX(aux_clientes!$C$2:$C$246,MATCH(LARGE(aux_clientes!$F$2:$F$246,A46),aux_clientes!$F$2:$F$246,0)) -> 1371.52 | D46: =INDEX(aux_clientes!$B$2:$B$246,MATCH(LARGE(aux_clientes!$F$2:$F$246,A46),aux_clientes!$F$2:$F$246,0)) -> 6 | E46: =C46/SUM(v_valor) -> 0.012543124 | F46: =SUM($E$38:E46) -> 0.13107415
A47: 10 | B47: =INDEX(aux_clientes!$A$2:$A$246,MATCH(LARGE(aux_clientes!$F$2:$F$246,A47),aux_clientes!$F$2:$F$246,0)) -> CLI-0151 | C47: =INDEX(aux_clientes!$C$2:$C$246,MATCH(LARGE(aux_clientes!$F$2:$F$246,A47),aux_clientes!$F$2:$F$246,0)) -> 1357.39 | D47: =INDEX(aux_clientes!$B$2:$B$246,MATCH(LARGE(aux_clientes!$F$2:$F$246,A47),aux_clientes!$F$2:$F$246,0)) -> 5 | E47: =C47/SUM(v_valor) -> 0.012413899 | F47: =SUM($E$38:E47) -> 0.14348805
A48: 11 | B48: =INDEX(aux_clientes!$A$2:$A$246,MATCH(LARGE(aux_clientes!$F$2:$F$246,A48),aux_clientes!$F$2:$F$246,0)) -> CLI-0222 | C48: =INDEX(aux_clientes!$C$2:$C$246,MATCH(LARGE(aux_clientes!$F$2:$F$246,A48),aux_clientes!$F$2:$F$246,0)) -> 1345.99 | D48: =INDEX(aux_clientes!$B$2:$B$246,MATCH(LARGE(aux_clientes!$F$2:$F$246,A48),aux_clientes!$F$2:$F$246,0)) -> 8 | E48: =C48/SUM(v_valor) -> 0.012309642 | F48: =SUM($E$38:E48) -> 0.15579769
A49: 12 | B49: =INDEX(aux_clientes!$A$2:$A$246,MATCH(LARGE(aux_clientes!$F$2:$F$246,A49),aux_clientes!$F$2:$F$246,0)) -> CLI-0177 | C49: =INDEX(aux_clientes!$C$2:$C$246,MATCH(LARGE(aux_clientes!$F$2:$F$246,A49),aux_clientes!$F$2:$F$246,0)) -> 1339.93 | D49: =INDEX(aux_clientes!$B$2:$B$246,MATCH(LARGE(aux_clientes!$F$2:$F$246,A49),aux_clientes!$F$2:$F$246,0)) -> 3 | E49: =C49/SUM(v_valor) -> 0.01225422 | F49: =SUM($E$38:E49) -> 0.16805191
...

Sheet 6_Desconto
A1: Bloco 6 — Preço e Desconto
A2: Perguntas 18 a 20 · exclui as 69 vendas com desconto imputado pela mediana
A4: 18. Distribuição da política de desconto
A5: Pergunta: como os descontos estão sendo aplicados na prática?
A6: Como ler: quantas vendas caem em cada faixa de desconto. Só descontos observados ou recalculados da própria venda.
A8: Faixa | B8: de (>) | C8: até (≤) | D8: Vendas | E8: % das vendas
A9: Sem desconto | B9: — | C9: 0 | D9: =COUNTIFS(v_desc,0,v_desc_origem,"<>imputado_mediana") -> 173 | E9: =D9/SUM($D$9:$D$15) -> 0.1858217
A10: até 1% | B10: 0 | C10: 1 | D10: =COUNTIFS(v_desc,">"&B10,v_desc,"<="&C10,v_desc_origem,"<>imputado_mediana") -> 145 | E10: =D10/SUM($D$9:$D$15) -> 0.15574651
A11: 1% a 2% | B11: 1 | C11: 2 | D11: =COUNTIFS(v_desc,">"&B11,v_desc,"<="&C11,v_desc_origem,"<>imputado_mediana") -> 170 | E11: =D11/SUM($D$9:$D$15) -> 0.18259936
A12: 2% a 3% | B12: 2 | C12: 3 | D12: =COUNTIFS(v_desc,">"&B12,v_desc,"<="&C12,v_desc_origem,"<>imputado_mediana") -> 108 | E12: =D12/SUM($D$9:$D$15) -> 0.1160043
A13: 3% a 5% | B13: 3 | C13: 5 | D13: =COUNTIFS(v_desc,">"&B13,v_desc,"<="&C13,v_desc_origem,"<>imputado_mediana") -> 166 | E13: =D13/SUM($D$9:$D$15) -> 0.1783029
A14: 5% a 10% | B14: 5 | C14: 10 | D14: =COUNTIFS(v_desc,">"&B14,v_desc,"<="&C14,v_desc_origem,"<>imputado_mediana") -> 127 | E14: =D14/SUM($D$9:$D$15) -> 0.13641246
A15: 10% a 20% | B15: 10 | C15: 20 | D15: =COUNTIFS(v_desc,">"&B15,v_desc,"<="&C15,v_desc_origem,"<>imputado_mediana") -> 42 | E15: =D15/SUM($D$9:$D$15) -> 0.045112782
A16: Total | D16: =SUM(D9:D15) -> 931
A17: Conferência: vendas consideradas | D17: =COUNTIFS(v_desc_origem,"<>imputado_mediana") -> 931
A19: Desconto médio | B19: =AVERAGEIFS(v_desc,v_desc_origem,"<>imputado_mediana") -> 2.8834694 | C19: valores em pontos percentuais
A20: Desconto mediano | B20: {=MEDIAN(IF((v_desc_origem<>"imputado_mediana"),v_desc))} -> 1.89
A21: Maior desconto | B21: =_xlfn.MAXIFS(v_desc,v_desc_origem,"<>imputado_mediana") -> 18
A23: As faixas (azul) são editáveis. A coluna 'até' de uma faixa deve ser igual à coluna 'de' da seguinte, para nenhuma venda ficar de fora — confira pela linha 'Conferência'.
A25: Sua conclusão:
A26: Escreva aqui, com suas palavras, o que a tabela e o gráfico mostram.
A31: 19. Desconto médio por categoria e canal
A32: Pergunta: onde a empresa concede mais desconto?
A33: Como ler: desconto médio em pontos percentuais para cada combinação. Células vazias = sem vendas na combinação. Cores mais fortes = mais desconto.
A35: Categoria | B35: Loja | C35: Site | D35: App | E35: Televendas | F35: Não informado
A36: Mercearia | B36: =IFERROR(AVERAGEIFS(v_desc,v_categoria,$A36,v_canal,B$35,v_desc_origem,"<>imputado_mediana"),"") -> 2.5669841 | C36: =IFERROR(AVERAGEIFS(v_desc,v_categoria,$A36,v_canal,C$35,v_desc_origem,"<>imputado_mediana"),"") -> 3.3582759 | D36: =IFERROR(AVERAGEIFS(v_desc,v_categoria,$A36,v_canal,D$35,v_desc_origem,"<>imputado_mediana"),"") -> 3.2075 | E36: =IFERROR(AVERAGEIFS(v_desc,v_categoria,$A36,v_canal,E$35,v_desc_origem,"<>imputado_mediana"),"") -> 2.6554545 | F36: =IFERROR(AVERAGEIFS(v_desc,v_categoria,$A36,v_canal,F$35,v_desc_origem,"<>imputado_mediana"),"") -> 3.3170455
A37: Bebidas | B37: =IFERROR(AVERAGEIFS(v_desc,v_categoria,$A37,v_canal,B$35,v_desc_origem,"<>imputado_mediana"),"") -> 2.8555714 | C37: =IFERROR(AVERAGEIFS(v_desc,v_categoria,$A37,v_canal,C$35,v_desc_origem,"<>imputado_mediana"),"") -> 2.58 | D37: =IFERROR(AVERAGEIFS(v_desc,v_categoria,$A37,v_canal,D$35,v_desc_origem,"<>imputado_mediana"),"") -> 2.9192308 | E37: =IFERROR(AVERAGEIFS(v_desc,v_categoria,$A37,v_canal,E$35,v_desc_origem,"<>imputado_mediana"),"") -> 6.69 | F37: =IFERROR(AVERAGEIFS(v_desc,v_categoria,$A37,v_canal,F$35,v_desc_origem,"<>imputado_mediana"),"") -> 2.7208
A38: Limpeza | B38: =IFERROR(AVERAGEIFS(v_desc,v_categoria,$A38,v_canal,B$35,v_desc_origem,"<>imputado_mediana"),"") -> 2.6581132 | C38: =IFERROR(AVERAGEIFS(v_desc,v_categoria,$A38,v_canal,C$35,v_desc_origem,"<>imputado_mediana"),"") -> 2.8845455 | D38: =IFERROR(AVERAGEIFS(v_desc,v_categoria,$A38,v_canal,D$35,v_desc_origem,"<>imputado_mediana"),"") -> 3.4020833 | E38: =IFERROR(AVERAGEIFS(v_desc,v_categoria,$A38,v_canal,E$35,v_desc_origem,"<>imputado_mediana"),"") -> 2.8533333 | F38: =IFERROR(AVERAGEIFS(v_desc,v_categoria,$A38,v_canal,F$35,v_desc_origem,"<>imputado_mediana"),"") -> 2.82075
A39: Frios | B39: =IFERROR(AVERAGEIFS(v_desc,v_categoria,$A39,v_canal,B$35,v_desc_origem,"<>imputado_mediana"),"") -> 4.1457576 | C39: =IFERROR(AVERAGEIFS(v_desc,v_categoria,$A39,v_canal,C$35,v_desc_origem,"<>imputado_mediana"),"") -> 2.282 | D39: =IFERROR(AVERAGEIFS(v_desc,v_categoria,$A39,v_canal,D$35,v_desc_origem,"<>imputado_mediana"),"") -> 2.4992308 | E39: =IFERROR(AVERAGEIFS(v_desc,v_categoria,$A39,v_canal,E$35,v_desc_origem,"<>imputado_mediana"),"") -> 0.69333333 | F39: =IFERROR(AVERAGEIFS(v_desc,v_categoria,$A39,v_canal,F$35,v_desc_origem,"<>imputado_mediana"),"") -> 2.2604545
A40: Higiene | B40: =IFERROR(AVERAGEIFS(v_desc,v_categoria,$A40,v_canal,B$35,v_desc_origem,"<>imputado_mediana"),"") -> 3.1941176 | C40: =IFERROR(AVERAGEIFS(v_desc,v_categoria,$A40,v_canal,C$35,v_desc_origem,"<>imputado_mediana"),"") -> 2.494375 | D40: =IFERROR(AVERAGEIFS(v_desc,v_categoria,$A40,v_canal,D$35,v_desc_origem,"<>imputado_mediana"),"") -> 4.0936364 | E40: =IFERROR(AVERAGEIFS(v_desc,v_categoria,$A40,v_canal,E$35,v_desc_origem,"<>imputado_mediana"),"") -> 3.3133333 | F40: =IFERROR(AVERAGEIFS(v_desc,v_categoria,$A40,v_canal,F$35,v_desc_origem,"<>imputado_mediana"),"") -> 2.7995
A41: Padaria | B41: =IFERROR(AVERAGEIFS(v_desc,v_categoria,$A41,v_canal,B$35,v_desc_origem,"<>imputado_mediana"),"") -> 2.5905882 | C41: =IFERROR(AVERAGEIFS(v_desc,v_categoria,$A41,v_canal,C$35,v_desc_origem,"<>imputado_mediana"),"") -> 3.1432143 | D41: =IFERROR(AVERAGEIFS(v_desc,v_categoria,$A41,v_canal,D$35,v_desc_origem,"<>imputado_mediana"),"") -> 2.6886364 | E41: =IFERROR(AVERAGEIFS(v_desc,v_categoria,$A41,v_canal,E$35,v_desc_origem,"<>imputado_mediana"),"") -> 3.268 | F41: =IFERROR(AVERAGEIFS(v_desc,v_categoria,$A41,v_canal,F$35,v_desc_origem,"<>imputado_mediana"),"") -> 2.495
A42: Hortifruti | B42: =IFERROR(AVERAGEIFS(v_desc,v_categoria,$A42,v_canal,B$35,v_desc_origem,"<>imputado_mediana"),"") -> 2.8978378 | C42: =IFERROR(AVERAGEIFS(v_desc,v_categoria,$A42,v_canal,C$35,v_desc_origem,"<>imputado_mediana"),"") -> 3.4145833 | D42: =IFERROR(AVERAGEIFS(v_desc,v_categoria,$A42,v_canal,D$35,v_desc_origem,"<>imputado_mediana"),"") -> 2.7025 | E42: =IFERROR(AVERAGEIFS(v_desc,v_categoria,$A42,v_canal,E$35,v_desc_origem,"<>imputado_mediana"),"") -> 0.795 | F42: =IFERROR(AVERAGEIFS(v_desc,v_categoria,$A42,v_canal,F$35,v_desc_origem,"<>imputado_mediana"),"") -> 2.2311111
A45: Sua conclusão:
A46: Escreva aqui, com suas palavras, o que a tabela e o gráfico mostram.
A51: 20. Relação entre desconto e valor da venda
A52: Pergunta: desconto maior gera venda maior?
A53: Como ler: a correlação vai de −1 a +1. Perto de zero = não há relação linear. É calculada pela fórmula de Pearson, passo a passo, só com descontos observados ou recalculados.
A55: Componente | C55: Valor
A56: n (vendas consideradas) | C56: =SUMPRODUCT(--(v_desc_origem<>"imputado_mediana")) -> 931
A57: Σx (desconto) | C57: =SUMPRODUCT((v_desc_origem<>"imputado_mediana")*v_desc) -> 2684.51
...

Sheet Dados
A1: id_venda | B1: data | C1: mes | D1: ano | E1: dia | F1: dia_semana | G1: cliente | H1: categoria | I1: canal | J1: uf | K1: quantidade | L1: preco_unit | M1: desconto_pct | N1: valor_total | O1: preco_origem | P1: desconto_origem | Q1: valor_origem
A2: 1 | B2: 45512 | C2: 8 | D2: 2024 | E2: 8 | F2: Quinta-feira | G2: CLI-0069 | H2: Limpeza | I2: Não informado | J2: BA | K2: 1 | L2: 21.67 | M2: 0.45 | N2: 50.63 | O2: imputado_mediana_categoria | P2: original | Q2: original
A3: 2 | B3: 45608 | C3: 11 | D3: 2024 | E3: 12 | F3: Terça-feira | G3: CLI-0050 | H3: Limpeza | I3: Loja | J3: RJ | K3: 4 | L3: 111.06 | M3: 4.91 | N3: 422.43 | O3: original | P3: original | Q3: original
A4: 3 | B4: 45543 | C4: 9 | D4: 2024 | E4: 8 | F4: Domingo | G4: CLI-0149 | H4: Padaria | I4: Loja | J4: NI | K4: 5 | L4: 10.73 | M4: 4.86 | N4: 51.04 | O4: original | P4: original | Q4: corrigido_decimal
A5: 4 | B5: 45389 | C5: 4 | D5: 2024 | E5: 7 | F5: Domingo | G5: CLI-0044 | H5: Bebidas | I5: Não informado | J5: SP | K5: 2 | L5: 87.89 | M5: 2.87 | N5: 170.74 | O5: original | P5: original | Q5: original
A6: 5 | B6: 45470 | C6: 6 | D6: 2024 | E6: 27 | F6: Quinta-feira | G6: CLI-0140 | H6: Hortifruti | I6: Loja | J6: SP | K6: 1 | L6: 8.1 | M6: 0.37 | N6: 8.07 | O6: original | P6: reconstruido | Q6: original
A7: 6 | B7: 45381 | C7: 3 | D7: 2024 | E7: 30 | F7: Sábado | G7: CLI-0127 | H7: Padaria | I7: Loja | J7: GO | K7: 4 | L7: 3.98 | M7: 3.84 | N7: 15.31 | O7: original | P7: original | Q7: original
A8: 7 | B8: 45396 | C8: 4 | D8: 2024 | E8: 14 | F8: Domingo | G8: CLI-0232 | H8: Mercearia | I8: Loja | J8: NI | K8: 3 | L8: 71.09 | M8: 1.79 | N8: 209.45 | O8: original | P8: reconstruido | Q8: original
A9: 8 | B9: 45637 | C9: 12 | D9: 2024 | E9: 11 | F9: Quarta-feira | G9: CLI-0091 | H9: Limpeza | I9: App | J9: NI | K9: 1 | L9: 4.4 | M9: 0 | N9: 4.4 | O9: original | P9: original | Q9: original
A10: 9 | B10: 45515 | C10: 8 | D10: 2024 | E10: 11 | F10: Domingo | G10: CLI-0177 | H10: Frios | I10: Loja | J10: NI | K10: 6 | L10: 82.02 | M10: 7.03 | N10: 457.52 | O10: original | P10: original | Q10: original
A11: 10 | B11: 45482 | C11: 7 | D11: 2024 | E11: 9 | F11: Terça-feira | G11: CLI-0109 | H11: Frios | I11: Loja | J11: MA | K11: 2 | L11: 207.34 | M11: 1.92 | N11: 406.72 | O11: original | P11: original | Q11: original
A12: 11 | B12: 45415 | C12: 5 | D12: 2024 | E12: 3 | F12: Sexta-feira | G12: CLI-0211 | H12: Padaria | I12: Não informado | J12: MG | K12: 1 | L12: 35.85 | M12: 0.7 | N12: 35.6 | O12: original | P12: original | Q12: original
A13: 12 | B13: 45655 | C13: 12 | D13: 2024 | E13: 29 | F13: Domingo | G13: CLI-0175 | H13: Frios | I13: Loja | J13: SP | K13: 1 | L13: 39.06 | M13: 0 | N13: 39.06 | O13: original | P13: reconstruido | Q13: original
... A1001: 1000 | B1001: 45345 | C1001: 2 | D1001: 2024 | E1001: 23 | F1001: Sexta-feira | G1001: CLI-0073 | H1001: Bebidas | I1001: Site | J1001: PE | K1001: 1 | L1001: 8.01 | M1001: 1.5 | N1001: 7.89 | O1001: original | P1001: reconstruido | Q1001: original

Sheet aux_clientes
A1: cliente | B1: compras | C1: receita | D1: última compra | E1: recência (dias) | F1: chave de ranking | G1: R | H1: F | I1: V | J1: RFV total | K1: segmento
A2: CLI-0001 | B2: =COUNTIFS(v_cliente,A2) -> 3 | C2: =SUMIFS(v_valor,v_cliente,A2) -> 350.47 | D2: =_xlfn.MAXIFS(v_data,v_cliente,A2) -> 45636 | E2: =rfv_ref-D2 -> 22 | F2: =C2+ROW()/10000000 -> 350.47 | G2: =IF(E2<=QUARTILE($E$2:$E$246,1),4,IF(E2<=QUARTILE($E$2:$E$246,2),3,IF(E2<=QUARTILE($E$2:$E$246,3),2,1))) -> 4 | H2: =IF(B2>QUARTILE($B$2:$B$246,3),4,IF(B2>QUARTILE($B$2:$B$246,2),3,IF(B2>QUARTILE($B$2:$B$246,1),2,1))) -> 1 | I2: =IF(C2>QUARTILE($C$2:$C$246,3),4,IF(C2>QUARTILE($C$2:$C$246,2),3,IF(C2>QUARTILE($C$2:$C$246,1),2,1))) -> 3 | J2: =G2+H2+I2 -> 8 | K2: =IF(J2>=rfv_campeoes,"Campeões",IF(J2>=rfv_leais,"Leais",IF(J2>=rfv_atencao,"Atenção","Em risco"))) -> Leais
A3: CLI-0002 | B3: =COUNTIFS(v_cliente,A3) -> 2 | C3: =SUMIFS(v_valor,v_cliente,A3) -> 95.78 | D3: =_xlfn.MAXIFS(v_data,v_cliente,A3) -> 45521 | E3: =rfv_ref-D3 -> 137 | F3: =C3+ROW()/10000000 -> 95.78 | G3: =IF(E3<=QUARTILE($E$2:$E$246,1),4,IF(E3<=QUARTILE($E$2:$E$246,2),3,IF(E3<=QUARTILE($E$2:$E$246,3),2,1))) -> 1 | H3: =IF(B3>QUARTILE($B$2:$B$246,3),4,IF(B3>QUARTILE($B$2:$B$246,2),3,IF(B3>QUARTILE($B$2:$B$246,1),2,1))) -> 1 | I3: =IF(C3>QUARTILE($C$2:$C$246,3),4,IF(C3>QUARTILE($C$2:$C$246,2),3,IF(C3>QUARTILE($C$2:$C$246,1),2,1))) -> 1 | J3: =G3+H3+I3 -> 3 | K3: =IF(J3>=rfv_campeoes,"Campeões",IF(J3>=rfv_leais,"Leais",IF(J3>=rfv_atencao,"Atenção","Em risco"))) -> Em risco
A4: CLI-0003 | B4: =COUNTIFS(v_cliente,A4) -> 4 | C4: =SUMIFS(v_valor,v_cliente,A4) -> 546.36 | D4: =_xlfn.MAXIFS(v_data,v_cliente,A4) -> 45627 | E4: =rfv_ref-D4 -> 31 | F4: =C4+ROW()/10000000 -> 546.36 | G4: =IF(E4<=QUARTILE($E$2:$E$246,1),4,IF(E4<=QUARTILE($E$2:$E$246,2),3,IF(E4<=QUARTILE($E$2:$E$246,3),2,1))) -> 3 | H4: =IF(B4>QUARTILE($B$2:$B$246,3),4,IF(B4>QUARTILE($B$2:$B$246,2),3,IF(B4>QUARTILE($B$2:$B$246,1),2,1))) -> 2 | I4: =IF(C4>QUARTILE($C$2:$C$246,3),4,IF(C4>QUARTILE($C$2:$C$246,2),3,IF(C4>QUARTILE($C$2:$C$246,1),2,1))) -> 3 | J4: =G4+H4+I4 -> 8 | K4: =IF(J4>=rfv_campeoes,"Campeões",IF(J4>=rfv_leais,"Leais",IF(J4>=rfv_atencao,"Atenção","Em risco"))) -> Leais
A5: CLI-0004 | B5: =COUNTIFS(v_cliente,A5) -> 6 | C5: =SUMIFS(v_valor,v_cliente,A5) -> 1371.52 | D5: =_xlfn.MAXIFS(v_data,v_cliente,A5) -> 45612 | E5: =rfv_ref-D5 -> 46 | F5: =C5+ROW()/10000000 -> 1371.52 | G5: =IF(E5<=QUARTILE($E$2:$E$246,1),4,IF(E5<=QUARTILE($E$2:$E$246,2),3,IF(E5<=QUARTILE($E$2:$E$246,3),2,1))) -> 3 | H5: =IF(B5>QUARTILE($B$2:$B$246,3),4,IF(B5>QUARTILE($B$2:$B$246,2),3,IF(B5>QUARTILE($B$2:$B$246,1),2,1))) -> 4 | I5: =IF(C5>QUARTILE($C$2:$C$246,3),4,IF(C5>QUARTILE($C$2:$C$246,2),3,IF(C5>QUARTILE($C$2:$C$246,1),2,1))) -> 4 | J5: =G5+H5+I5 -> 11 | K5: =IF(J5>=rfv_campeoes,"Campeões",IF(J5>=rfv_leais,"Leais",IF(J5>=rfv_atencao,"Atenção","Em risco"))) -> Campeões
A6: CLI-0005 | B6: =COUNTIFS(v_cliente,A6) -> 1 | C6: =SUMIFS(v_valor,v_cliente,A6) -> 40.74 | D6: =_xlfn.MAXIFS(v_data,v_cliente,A6) -> 45536 | E6: =rfv_ref-D6 -> 122 | F6: =C6+ROW()/10000000 -> 40.740001 | G6: =IF(E6<=QUARTILE($E$2:$E$246,1),4,IF(E6<=QUARTILE($E$2:$E$246,2),3,IF(E6<=QUARTILE($E$2:$E$246,3),2,1))) -> 2 | H6: =IF(B6>QUARTILE($B$2:$B$246,3),4,IF(B6>QUARTILE($B$2:$B$246,2),3,IF(B6>QUARTILE($B$2:$B$246,1),2,1))) -> 1 | I6: =IF(C6>QUARTILE($C$2:$C$246,3),4,IF(C6>QUARTILE($C$2:$C$246,2),3,IF(C6>QUARTILE($C$2:$C$246,1),2,1))) -> 1 | J6: =G6+H6+I6 -> 4 | K6: =IF(J6>=rfv_campeoes,"Campeões",IF(J6>=rfv_leais,"Leais",IF(J6>=rfv_atencao,"Atenção","Em risco"))) -> Em risco
A7: CLI-0006 | B7: =COUNTIFS(v_cliente,A7) -> 2 | C7: =SUMIFS(v_valor,v_cliente,A7) -> 82.01 | D7: =_xlfn.MAXIFS(v_data,v_cliente,A7) -> 45452 | E7: =rfv_ref-D7 -> 206 | F7: =C7+ROW()/10000000 -> 82.010001 | G7: =IF(E7<=QUARTILE($E$2:$E$246,1),4,IF(E7<=QUARTILE($E$2:$E$246,2),3,IF(E7<=QUARTILE($E$2:$E$246,3),2,1))) -> 1 | H7: =IF(B7>QUARTILE($B$2:$B$246,3),4,IF(B7>QUARTILE($B$2:$B$246,2),3,IF(B7>QUARTILE($B$2:$B$246,1),2,1))) -> 1 | I7: =IF(C7>QUARTILE($C$2:$C$246,3),4,IF(C7>QUARTILE($C$2:$C$246,2),3,IF(C7>QUARTILE($C$2:$C$246,1),2,1))) -> 1 | J7: =G7+H7+I7 -> 3 | K7: =IF(J7>=rfv_campeoes,"Campeões",IF(J7>=rfv_leais,"Leais",IF(J7>=rfv_atencao,"Atenção","Em risco"))) -> Em risco
A8: CLI-0007 | B8: =COUNTIFS(v_cliente,A8) -> 7 | C8: =SUMIFS(v_valor,v_cliente,A8) -> 399.45 | D8: =_xlfn.MAXIFS(v_data,v_cliente,A8) -> 45651 | E8: =rfv_ref-D8 -> 7 | F8: =C8+ROW()/10000000 -> 399.45 | G8: =IF(E8<=QUARTILE($E$2:$E$246,1),4,IF(E8<=QUARTILE($E$2:$E$246,2),3,IF(E8<=QUARTILE($E$2:$E$246,3),2,1))) -> 4 | H8: =IF(B8>QUARTILE($B$2:$B$246,3),4,IF(B8>QUARTILE($B$2:$B$246,2),3,IF(B8>QUARTILE($B$2:$B$246,1),2,1))) -> 4 | I8: =IF(C8>QUARTILE($C$2:$C$246,3),4,IF(C8>QUARTILE($C$2:$C$246,2),3,IF(C8>QUARTILE($C$2:$C$246,1),2,1))) -> 3 | J8: =G8+H8+I8 -> 11 | K8: =IF(J8>=rfv_campeoes,"Campeões",IF(J8>=rfv_leais,"Leais",IF(J8>=rfv_atencao,"Atenção","Em risco"))) -> Campeões
A9: CLI-0008 | B9: =COUNTIFS(v_cliente,A9) -> 2 | C9: =SUMIFS(v_valor,v_cliente,A9) -> 141.85 | D9: =_xlfn.MAXIFS(v_data,v_cliente,A9) -> 45453 | E9: =rfv_ref-D9 -> 205 | F9: =C9+ROW()/10000000 -> 141.85 | G9: =IF(E9<=QUARTILE($E$2:$E$246,1),4,IF(E9<=QUARTILE($E$2:$E$246,2),3,IF(E9<=QUARTILE($E$2:$E$246,3),2,1))) -> 1 | H9: =IF(B9>QUARTILE($B$2:$B$246,3),4,IF(B9>QUARTILE($B$2:$B$246,2),3,IF(B9>QUARTILE($B$2:$B$246,1),2,1))) -> 1 | I9: =IF(C9>QUARTILE($C$2:$C$246,3),4,IF(C9>QUARTILE($C$2:$C$246,2),3,IF(C9>QUARTILE($C$2:$C$246,1),2,1))) -> 1 | J9: =G9+H9+I9 -> 3 | K9: =IF(J9>=rfv_campeoes,"Campeões",IF(J9>=rfv_leais,"Leais",IF(J9>=rfv_atencao,"Atenção","Em risco"))) -> Em risco
A10: CLI-0009 | B10: =COUNTIFS(v_cliente,A10) -> 4 | C10: =SUMIFS(v_valor,v_cliente,A10) -> 414.08 | D10: =_xlfn.MAXIFS(v_data,v_cliente,A10) -> 45622 | E10: =rfv_ref-D10 -> 36 | F10: =C10+ROW()/10000000 -> 414.08 | G10: =IF(E10<=QUARTILE($E$2:$E$246,1),4,IF(E10<=QUARTILE($E$2:$E$246,2),3,IF(E10<=QUARTILE($E$2:$E$246,3),2,1))) -> 3 | H10: =IF(B10>QUARTILE($B$2:$B$246,3),4,IF(B10>QUARTILE($B$2:$B$246,2),3,IF(B10>QUARTILE($B$2:$B$246,1),2,1))) -> 2 | I10: =IF(C10>QUARTILE($C$2:$C$246,3),4,IF(C10>QUARTILE($C$2:$C$246,2),3,IF(C10>QUARTILE($C$2:$C$246,1),2,1))) -> 3 | J10: =G10+H10+I10 -> 8 | K10: =IF(J10>=rfv_campeoes,"Campeões",IF(J10>=rfv_leais,"Leais",IF(J10>=rfv_atencao,"Atenção","Em risco"))) -> Leais
A11: CLI-0010 | B11: =COUNTIFS(v_cliente,A11) -> 2 | C11: =SUMIFS(v_valor,v_cliente,A11) -> 319.69 | D11: =_xlfn.MAXIFS(v_data,v_cliente,A11) -> 45654 | E11: =rfv_ref-D11 -> 4 | F11: =C11+ROW()/10000000 -> 319.69 | G11: =IF(E11<=QUARTILE($E$2:$E$246,1),4,IF(E11<=QUARTILE($E$2:$E$246,2),3,IF(E11<=QUARTILE($E$2:$E$246,3),2,1))) -> 4 | H11: =IF(B11>QUARTILE($B$2:$B$246,3),4,IF(B11>QUARTILE($B$2:$B$246,2),3,IF(B11>QUARTILE($B$2:$B$246,1),2,1))) -> 1 | I11: =IF(C11>QUARTILE($C$2:$C$246,3),4,IF(C11>QUARTILE($C$2:$C$246,2),3,IF(C11>QUARTILE($C$2:$C$246,1),2,1))) -> 2 | J11: =G11+H11+I11 -> 7 | K11: =IF(J11>=rfv_campeoes,"Campeões",IF(J11>=rfv_leais,"Leais",IF(J11>=rfv_atencao,"Atenção","Em risco"))) -> Leais
A12: CLI-0011 | B12: =COUNTIFS(v_cliente,A12) -> 6 | C12: =SUMIFS(v_valor,v_cliente,A12) -> 356.04 | D12: =_xlfn.MAXIFS(v_data,v_cliente,A12) -> 45588 | E12: =rfv_ref-D12 -> 70 | F12: =C12+ROW()/10000000 -> 356.04 | G12: =IF(E12<=QUARTILE($E$2:$E$246,1),4,IF(E12<=QUARTILE($E$2:$E$246,2),3,IF(E12<=QUARTILE($E$2:$E$246,3),2,1))) -> 2 | H12: =IF(B12>QUARTILE($B$2:$B$246,3),4,IF(B12>QUARTILE($B$2:$B$246,2),3,IF(B12>QUARTILE($B$2:$B$246,1),2,1))) -> 4 | I12: =IF(C12>QUARTILE($C$2:$C$246,3),4,IF(C12>QUARTILE($C$2:$C$246,2),3,IF(C12>QUARTILE($C$2:$C$246,1),2,1))) -> 3 | J12: =G12+H12+I12 -> 9 | K12: =IF(J12>=rfv_campeoes,"Campeões",IF(J12>=rfv_leais,"Leais",IF(J12>=rfv_atencao,"Atenção","Em risco"))) -> Leais
A13: CLI-0012 | B13: =COUNTIFS(v_cliente,A13) -> 3 | C13: =SUMIFS(v_valor,v_cliente,A13) -> 183.28 | D13: =_xlfn.MAXIFS(v_data,v_cliente,A13) -> 45657 | E13: =rfv_ref-D13 -> 1 | F13: =C13+ROW()/10000000 -> 183.28 | G13: =IF(E13<=QUARTILE($E$2:$E$246,1),4,IF(E13<=QUARTILE($E$2:$E$246,2),3,IF(E13<=QUARTILE($E$2:$E$246,3),2,1))) -> 4 | H13: =IF(B13>QUARTILE($B$2:$B$246,3),4,IF(B13>QUARTILE($B$2:$B$246,2),3,IF(B13>QUARTILE($B$2:$B$246,1),2,1))) -> 1 | I13: =IF(C13>QUARTILE($C$2:$C$246,3),4,IF(C13>QUARTILE($C$2:$C$246,2),3,IF(C13>QUARTILE($C$2:$C$246,1),2,1))) -> 2 | J13: =G13+H13+I13 -> 7 | K13: =IF(J13>=rfv_campeoes,"Campeões",IF(J13>=rfv_leais,"Leais",IF(J13>=rfv_atencao,"Atenção","Em risco"))) -> Leais
... A246: CLI-0250 | B246: =COUNTIFS(v_cliente,A246) -> 7 | C246: =SUMIFS(v_valor,v_cliente,A246) -> 1718.86 | D246: =_xlfn.MAXIFS(v_data,v_cliente,A246) -> 45578 | E246: =rfv_ref-D246 -> 80 | F246: =C246+ROW()/10000000 -> 1718.86 | G246: =IF(E246<=QUARTILE($E$2:$E$246,1),4,IF(E246<=QUARTILE($E$2:$E$246,2),3,IF(E246<=QUARTILE($E$2:$E$246,3),2,1))) -> 2 | H246: =IF(B246>QUARTILE($B$2:$B$246,3),4,IF(B246>QUARTILE($B$2:$B$246,2),3,IF(B246>QUARTILE($B$2:$B$246,1),2,1))) -> 4 | I246: =IF(C246>QUARTILE($C$2:$C$246,3),4,IF(C246>QUARTILE($C$2:$C$246,2),3,IF(C246>QUARTILE($C$2:$C$246,1),2,1))) -> 4 | J246: =G246+H246+I246 -> 10 | K246: =IF(J246>=rfv_campeoes,"Campeões",IF(J246>=rfv_leais,"Leais",IF(J246>=rfv_atencao,"Atenção","Em risco"))) -> Campeões

Sheet aux_pareto
A1: posição | B1: valor da venda | C1: acumulado | D1: % acumulado da receita | E1: % das vendas
A2: 1 | B2: =LARGE(v_valor,A2) -> 1462.48 | C2: =B2 -> 1462.48 | D2: =C2/SUM(v_valor) -> 0.013374991 | E2: =A2/1000 -> 0.001
A3: 2 | B3: =LARGE(v_valor,A3) -> 1253.88 | C3: =C2+B3 -> 2716.36 | D3: =C3/SUM(v_valor) -> 0.024842248 | E3: =A3/1000 -> 0.002
A4: 3 | B4: =LARGE(v_valor,A4) -> 1221.59 | C4: =C3+B4 -> 3937.95 | D4: =C4/SUM(v_valor) -> 0.0360142 | E4: =A4/1000 -> 0.003
A5: 4 | B5: =LARGE(v_valor,A5) -> 1215.34 | C5: =C4+B5 -> 5153.29 | D5: =C5/SUM(v_valor) -> 0.047128993 | E5: =A5/1000 -> 0.004
A6: 5 | B6: =LARGE(v_valor,A6) -> 1102.86 | C6: =C5+B6 -> 6256.15 | D6: =C6/SUM(v_valor) -> 0.057215109 | E6: =A6/1000 -> 0.005
A7: 6 | B7: =LARGE(v_valor,A7) -> 1033.5 | C7: =C6+B7 -> 7289.65 | D7: =C7/SUM(v_valor) -> 0.066666898 | E7: =A7/1000 -> 0.006
